<?xml version="1.0" encoding="UTF-8"?>
<testng-results skipped="0" failed="4" ignored="0" total="5" passed="1">
  <reporter-output>
  </reporter-output>
  <suite name="Suite" duration-ms="59324" started-at="2020-06-18T14:52:32Z" finished-at="2020-06-18T14:53:31Z">
    <groups>
    </groups>
    <test name="Test" duration-ms="59324" started-at="2020-06-18T14:52:32Z" finished-at="2020-06-18T14:53:31Z">
      <class name="com.bridgelabz.testcases.TC_AdminLogin_01">
        <test-method status="PASS" signature="setup(java.lang.String)[pri:0, instance:com.bridgelabz.testcases.TC_AdminLogin_01@6fd02e5]" name="setup" is-config="true" duration-ms="7734" started-at="2020-06-18T14:52:32Z" finished-at="2020-06-18T14:52:40Z">
          <params>
            <param index="0">
              <value>
                <![CDATA[firefox]]>
              </value>
            </param>
          </params>
          <reporter-output>
          </reporter-output>
        </test-method> <!-- setup -->
        <test-method status="FAIL" signature="validatetingWithInValidCridential()[pri:0, instance:com.bridgelabz.testcases.TC_AdminLogin_01@6fd02e5]" name="validatetingWithInValidCridential" duration-ms="13918" started-at="2020-06-18T14:52:40Z" finished-at="2020-06-18T14:52:54Z">
          <exception class="java.lang.AssertionError">
            <message>
              <![CDATA[expected [true] but found [false]]]>
            </message>
            <full-stacktrace>
              <![CDATA[java.lang.AssertionError: expected [true] but found [false]
at org.testng.Assert.fail(Assert.java:96)
at org.testng.Assert.failNotEquals(Assert.java:776)
at org.testng.Assert.assertTrue(Assert.java:44)
at org.testng.Assert.assertTrue(Assert.java:54)
at com.bridgelabz.testcases.TC_AdminLogin_01.adminLogin(TC_AdminLogin_01.java:76)
at com.bridgelabz.testcases.TC_AdminLogin_01.validatetingWithInValidCridential(TC_AdminLogin_01.java:25)
at sun.reflect.NativeMethodAccessorImpl.invoke0(Native Method)
at sun.reflect.NativeMethodAccessorImpl.invoke(NativeMethodAccessorImpl.java:62)
at sun.reflect.DelegatingMethodAccessorImpl.invoke(DelegatingMethodAccessorImpl.java:43)
at java.lang.reflect.Method.invoke(Method.java:498)
at org.testng.internal.MethodInvocationHelper.invokeMethod(MethodInvocationHelper.java:124)
at org.testng.internal.Invoker.invokeMethod(Invoker.java:583)
at org.testng.internal.Invoker.invokeTestMethod(Invoker.java:719)
at org.testng.internal.Invoker.invokeTestMethods(Invoker.java:989)
at org.testng.internal.TestMethodWorker.invokeTestMethods(TestMethodWorker.java:125)
at org.testng.internal.TestMethodWorker.run(TestMethodWorker.java:109)
at org.testng.TestRunner.privateRun(TestRunner.java:648)
at org.testng.TestRunner.run(TestRunner.java:505)
at org.testng.SuiteRunner.runTest(SuiteRunner.java:455)
at org.testng.SuiteRunner.runSequentially(SuiteRunner.java:450)
at org.testng.SuiteRunner.privateRun(SuiteRunner.java:415)
at org.testng.SuiteRunner.run(SuiteRunner.java:364)
at org.testng.SuiteRunnerWorker.runSuite(SuiteRunnerWorker.java:52)
at org.testng.SuiteRunnerWorker.run(SuiteRunnerWorker.java:84)
at org.testng.TestNG.runSuitesSequentially(TestNG.java:1208)
at org.testng.TestNG.runSuitesLocally(TestNG.java:1137)
at org.testng.TestNG.runSuites(TestNG.java:1049)
at org.testng.TestNG.run(TestNG.java:1017)
at org.testng.remote.AbstractRemoteTestNG.run(AbstractRemoteTestNG.java:115)
at org.testng.remote.RemoteTestNG.initAndRun(RemoteTestNG.java:251)
at org.testng.remote.RemoteTestNG.main(RemoteTestNG.java:77)
]]>
            </full-stacktrace>
          </exception> <!-- java.lang.AssertionError -->
          <reporter-output>
          </reporter-output>
        </test-method> <!-- validatetingWithInValidCridential -->
        <test-method status="FAIL" signature="validatetingWithInValidEmail()[pri:0, instance:com.bridgelabz.testcases.TC_AdminLogin_01@6fd02e5]" name="validatetingWithInValidEmail" duration-ms="9764" started-at="2020-06-18T14:52:54Z" finished-at="2020-06-18T14:53:04Z">
          <exception class="java.lang.AssertionError">
            <message>
              <![CDATA[expected [true] but found [false]]]>
            </message>
            <full-stacktrace>
              <![CDATA[java.lang.AssertionError: expected [true] but found [false]
at org.testng.Assert.fail(Assert.java:96)
at org.testng.Assert.failNotEquals(Assert.java:776)
at org.testng.Assert.assertTrue(Assert.java:44)
at org.testng.Assert.assertTrue(Assert.java:54)
at com.bridgelabz.testcases.TC_AdminLogin_01.adminLogin(TC_AdminLogin_01.java:76)
at com.bridgelabz.testcases.TC_AdminLogin_01.validatetingWithInValidEmail(TC_AdminLogin_01.java:33)
at sun.reflect.NativeMethodAccessorImpl.invoke0(Native Method)
at sun.reflect.NativeMethodAccessorImpl.invoke(NativeMethodAccessorImpl.java:62)
at sun.reflect.DelegatingMethodAccessorImpl.invoke(DelegatingMethodAccessorImpl.java:43)
at java.lang.reflect.Method.invoke(Method.java:498)
at org.testng.internal.MethodInvocationHelper.invokeMethod(MethodInvocationHelper.java:124)
at org.testng.internal.Invoker.invokeMethod(Invoker.java:583)
at org.testng.internal.Invoker.invokeTestMethod(Invoker.java:719)
at org.testng.internal.Invoker.invokeTestMethods(Invoker.java:989)
at org.testng.internal.TestMethodWorker.invokeTestMethods(TestMethodWorker.java:125)
at org.testng.internal.TestMethodWorker.run(TestMethodWorker.java:109)
at org.testng.TestRunner.privateRun(TestRunner.java:648)
at org.testng.TestRunner.run(TestRunner.java:505)
at org.testng.SuiteRunner.runTest(SuiteRunner.java:455)
at org.testng.SuiteRunner.runSequentially(SuiteRunner.java:450)
at org.testng.SuiteRunner.privateRun(SuiteRunner.java:415)
at org.testng.SuiteRunner.run(SuiteRunner.java:364)
at org.testng.SuiteRunnerWorker.runSuite(SuiteRunnerWorker.java:52)
at org.testng.SuiteRunnerWorker.run(SuiteRunnerWorker.java:84)
at org.testng.TestNG.runSuitesSequentially(TestNG.java:1208)
at org.testng.TestNG.runSuitesLocally(TestNG.java:1137)
at org.testng.TestNG.runSuites(TestNG.java:1049)
at org.testng.TestNG.run(TestNG.java:1017)
at org.testng.remote.AbstractRemoteTestNG.run(AbstractRemoteTestNG.java:115)
at org.testng.remote.RemoteTestNG.initAndRun(RemoteTestNG.java:251)
at org.testng.remote.RemoteTestNG.main(RemoteTestNG.java:77)
]]>
            </full-stacktrace>
          </exception> <!-- java.lang.AssertionError -->
          <reporter-output>
          </reporter-output>
        </test-method> <!-- validatetingWithInValidEmail -->
        <test-method status="FAIL" signature="validatetingWithIvalidFormatedOfEmailAndPassword()[pri:0, instance:com.bridgelabz.testcases.TC_AdminLogin_01@6fd02e5]" name="validatetingWithIvalidFormatedOfEmailAndPassword" duration-ms="929" started-at="2020-06-18T14:53:04Z" finished-at="2020-06-18T14:53:05Z">
          <exception class="java.lang.IllegalArgumentException">
            <message>
              <![CDATA[Keys to send should be a not null CharSequence]]>
            </message>
            <full-stacktrace>
              <![CDATA[java.lang.IllegalArgumentException: Keys to send should be a not null CharSequence
at org.openqa.selenium.remote.RemoteWebElement.sendKeys(RemoteWebElement.java:97)
at sun.reflect.NativeMethodAccessorImpl.invoke0(Native Method)
at sun.reflect.NativeMethodAccessorImpl.invoke(NativeMethodAccessorImpl.java:62)
at sun.reflect.DelegatingMethodAccessorImpl.invoke(DelegatingMethodAccessorImpl.java:43)
at java.lang.reflect.Method.invoke(Method.java:498)
at org.openqa.selenium.support.pagefactory.internal.LocatingElementHandler.invoke(LocatingElementHandler.java:51)
at com.sun.proxy.$Proxy11.sendKeys(Unknown Source)
at com.bridgelabz.pageObjects.UserLogin.setEmailAddress(UserLogin.java:34)
at com.bridgelabz.testcases.TC_AdminLogin_01.adminLogin(TC_AdminLogin_01.java:58)
at com.bridgelabz.testcases.TC_AdminLogin_01.validatetingWithIvalidFormatedOfEmailAndPassword(TC_AdminLogin_01.java:49)
at sun.reflect.NativeMethodAccessorImpl.invoke0(Native Method)
at sun.reflect.NativeMethodAccessorImpl.invoke(NativeMethodAccessorImpl.java:62)
at sun.reflect.DelegatingMethodAccessorImpl.invoke(DelegatingMethodAccessorImpl.java:43)
at java.lang.reflect.Method.invoke(Method.java:498)
at org.testng.internal.MethodInvocationHelper.invokeMethod(MethodInvocationHelper.java:124)
at org.testng.internal.Invoker.invokeMethod(Invoker.java:583)
at org.testng.internal.Invoker.invokeTestMethod(Invoker.java:719)
at org.testng.internal.Invoker.invokeTestMethods(Invoker.java:989)
at org.testng.internal.TestMethodWorker.invokeTestMethods(TestMethodWorker.java:125)
at org.testng.internal.TestMethodWorker.run(TestMethodWorker.java:109)
at org.testng.TestRunner.privateRun(TestRunner.java:648)
at org.testng.TestRunner.run(TestRunner.java:505)
at org.testng.SuiteRunner.runTest(SuiteRunner.java:455)
at org.testng.SuiteRunner.runSequentially(SuiteRunner.java:450)
at org.testng.SuiteRunner.privateRun(SuiteRunner.java:415)
at org.testng.SuiteRunner.run(SuiteRunner.java:364)
at org.testng.SuiteRunnerWorker.runSuite(SuiteRunnerWorker.java:52)
at org.testng.SuiteRunnerWorker.run(SuiteRunnerWorker.java:84)
at org.testng.TestNG.runSuitesSequentially(TestNG.java:1208)
at org.testng.TestNG.runSuitesLocally(TestNG.java:1137)
at org.testng.TestNG.runSuites(TestNG.java:1049)
at org.testng.TestNG.run(TestNG.java:1017)
at org.testng.remote.AbstractRemoteTestNG.run(AbstractRemoteTestNG.java:115)
at org.testng.remote.RemoteTestNG.initAndRun(RemoteTestNG.java:251)
at org.testng.remote.RemoteTestNG.main(RemoteTestNG.java:77)
]]>
            </full-stacktrace>
          </exception> <!-- java.lang.IllegalArgumentException -->
          <reporter-output>
          </reporter-output>
        </test-method> <!-- validatetingWithIvalidFormatedOfEmailAndPassword -->
        <test-method status="PASS" signature="validatetingWithValidCridential()[pri:0, instance:com.bridgelabz.testcases.TC_AdminLogin_01@6fd02e5]" name="validatetingWithValidCridential" duration-ms="12531" started-at="2020-06-18T14:53:05Z" finished-at="2020-06-18T14:53:17Z">
          <reporter-output>
          </reporter-output>
        </test-method> <!-- validatetingWithValidCridential -->
        <test-method status="FAIL" signature="validatetingWithValidEmailButInvalidPassword()[pri:0, instance:com.bridgelabz.testcases.TC_AdminLogin_01@6fd02e5]" name="validatetingWithValidEmailButInvalidPassword" duration-ms="11157" started-at="2020-06-18T14:53:17Z" finished-at="2020-06-18T14:53:28Z">
          <exception class="java.lang.AssertionError">
            <message>
              <![CDATA[expected [true] but found [false]]]>
            </message>
            <full-stacktrace>
              <![CDATA[java.lang.AssertionError: expected [true] but found [false]
at org.testng.Assert.fail(Assert.java:96)
at org.testng.Assert.failNotEquals(Assert.java:776)
at org.testng.Assert.assertTrue(Assert.java:44)
at org.testng.Assert.assertTrue(Assert.java:54)
at com.bridgelabz.testcases.TC_AdminLogin_01.adminLogin(TC_AdminLogin_01.java:76)
at com.bridgelabz.testcases.TC_AdminLogin_01.validatetingWithValidEmailButInvalidPassword(TC_AdminLogin_01.java:41)
at sun.reflect.NativeMethodAccessorImpl.invoke0(Native Method)
at sun.reflect.NativeMethodAccessorImpl.invoke(NativeMethodAccessorImpl.java:62)
at sun.reflect.DelegatingMethodAccessorImpl.invoke(DelegatingMethodAccessorImpl.java:43)
at java.lang.reflect.Method.invoke(Method.java:498)
at org.testng.internal.MethodInvocationHelper.invokeMethod(MethodInvocationHelper.java:124)
at org.testng.internal.Invoker.invokeMethod(Invoker.java:583)
at org.testng.internal.Invoker.invokeTestMethod(Invoker.java:719)
at org.testng.internal.Invoker.invokeTestMethods(Invoker.java:989)
at org.testng.internal.TestMethodWorker.invokeTestMethods(TestMethodWorker.java:125)
at org.testng.internal.TestMethodWorker.run(TestMethodWorker.java:109)
at org.testng.TestRunner.privateRun(TestRunner.java:648)
at org.testng.TestRunner.run(TestRunner.java:505)
at org.testng.SuiteRunner.runTest(SuiteRunner.java:455)
at org.testng.SuiteRunner.runSequentially(SuiteRunner.java:450)
at org.testng.SuiteRunner.privateRun(SuiteRunner.java:415)
at org.testng.SuiteRunner.run(SuiteRunner.java:364)
at org.testng.SuiteRunnerWorker.runSuite(SuiteRunnerWorker.java:52)
at org.testng.SuiteRunnerWorker.run(SuiteRunnerWorker.java:84)
at org.testng.TestNG.runSuitesSequentially(TestNG.java:1208)
at org.testng.TestNG.runSuitesLocally(TestNG.java:1137)
at org.testng.TestNG.runSuites(TestNG.java:1049)
at org.testng.TestNG.run(TestNG.java:1017)
at org.testng.remote.AbstractRemoteTestNG.run(AbstractRemoteTestNG.java:115)
at org.testng.remote.RemoteTestNG.initAndRun(RemoteTestNG.java:251)
at org.testng.remote.RemoteTestNG.main(RemoteTestNG.java:77)
]]>
            </full-stacktrace>
          </exception> <!-- java.lang.AssertionError -->
          <reporter-output>
          </reporter-output>
        </test-method> <!-- validatetingWithValidEmailButInvalidPassword -->
        <test-method status="PASS" signature="tearDown()[pri:0, instance:com.bridgelabz.testcases.TC_AdminLogin_01@6fd02e5]" name="tearDown" is-config="true" duration-ms="2959" started-at="2020-06-18T14:53:28Z" finished-at="2020-06-18T14:53:31Z">
          <reporter-output>
          </reporter-output>
        </test-method> <!-- tearDown -->
      </class> <!-- com.bridgelabz.testcases.TC_AdminLogin_01 -->
    </test> <!-- Test -->
  </suite> <!-- Suite -->
</testng-results>
